{
    "registryname": "thermobakery",
    "localizedname": "Thermonuclear Bakery",
    "requires-blueprint": true,
    "color": "915E87",
    "parts": [
        {
            "x": -1,
            "y": 0,
            "z": 0,
            "elements": [
                "modularmachinery:blockcasing",
                "modularmachinery:blockinputitem",
                "modularmachinery:blockinputenergy",
                "modularmachinery:blockoutputitem"
            ]
        },
        {
            "x": 2,
            "y": 4,
            "z": 2,
            "elements": [
                "modularmachinery:blockcasing",
                "modularmachinery:blockinputitem",
                "modularmachinery:blockinputenergy",
                "modularmachinery:blockoutputitem"
            ]
        },
        {
            "x": 1,
            "y": 2,
            "z": 1,
            "elements": [
                "gregtech:machine_casing@9"
            ]
        },
        {
            "x": -2,
            "y": 0,
            "z": 0,
            "elements": [
                "modularmachinery:blockcasing",
                "modularmachinery:blockinputitem",
                "modularmachinery:blockinputenergy",
                "modularmachinery:blockoutputitem"
            ]
        },
        {
            "x": 2,
            "y": 2,
            "z": 1,
            "elements": [
                "gregtech:wire_coil@8"
            ]
        },
        {
            "x": 1,
            "y": 0,
            "z": 0,
            "elements": [
                "modularmachinery:blockcasing",
                "modularmachinery:blockinputitem",
                "modularmachinery:blockinputenergy",
                "modularmachinery:blockoutputitem"
            ]
        },
        {
            "x": 2,
            "y": 0,
            "z": 0,
            "elements": [
                "modularmachinery:blockcasing",
                "modularmachinery:blockinputitem",
                "modularmachinery:blockinputenergy",
                "modularmachinery:blockoutputitem"
            ]
        },
        {
            "x": -2,
            "y": 0,
            "z": 4,
            "elements": [
                "modularmachinery:blockcasing",
                "modularmachinery:blockinputitem",
                "modularmachinery:blockinputenergy",
                "modularmachinery:blockoutputitem"
            ]
        },
        {
            "x": -1,
            "y": 0,
            "z": 4,
            "elements": [
                "modularmachinery:blockcasing",
                "modularmachinery:blockinputitem",
                "modularmachinery:blockinputenergy",
                "modularmachinery:blockoutputitem"
            ]
        },
        {
            "x": 0,
            "y": 0,
            "z": 4,
            "elements": [
                "modularmachinery:blockcasing",
                "modularmachinery:blockinputitem",
                "modularmachinery:blockinputenergy",
                "modularmachinery:blockoutputitem"
            ]
        },
        {
            "x": 1,
            "y": 0,
            "z": 4,
            "elements": [
                "modularmachinery:blockcasing",
                "modularmachinery:blockinputitem",
                "modularmachinery:blockinputenergy",
                "modularmachinery:blockoutputitem"
            ]
        },
        {
            "x": 2,
            "y": 0,
            "z": 4,
            "elements": [
                "modularmachinery:blockcasing",
                "modularmachinery:blockinputitem",
                "modularmachinery:blockinputenergy",
                "modularmachinery:blockoutputitem"
            ]
        },
        {
            "x": -2,
            "y": 3,
            "z": 1,
            "elements": [
                "gregtech:wire_coil@8"
            ]
        },
        {
            "x": -2,
            "y": 1,
            "z": 0,
            "elements": [
                "techreborn:fusion_coil@0"
            ]
        },
        {
            "x": -1,
            "y": 3,
            "z": 1,
            "elements": [
                "gregtech:machine_casing@9"
            ]
        },
        {
            "x": 0,
            "y": 3,
            "z": 1,
            "elements": [
                "gregtech:machine_casing@9"
            ]
        },
        {
            "x": -1,
            "y": 1,
            "z": 0,
            "elements": [
                "gregtech:wire_coil@8"
            ]
        },
        {
            "x": 1,
            "y": 3,
            "z": 1,
            "elements": [
                "gregtech:machine_casing@9"
            ]
        },
        {
            "x": 0,
            "y": 1,
            "z": 0,
            "elements": [
                "gregtech:wire_coil@8"
            ]
        },
        {
            "x": 2,
            "y": 3,
            "z": 1,
            "elements": [
                "gregtech:wire_coil@8"
            ]
        },
        {
            "x": 1,
            "y": 1,
            "z": 0,
            "elements": [
                "gregtech:wire_coil@8"
            ]
        },
        {
            "x": -2,
            "y": 1,
            "z": 4,
            "elements": [
                "techreborn:fusion_coil@0"
            ]
        },
        {
            "x": 2,
            "y": 1,
            "z": 0,
            "elements": [
                "techreborn:fusion_coil@0"
            ]
        },
        {
            "x": -1,
            "y": 1,
            "z": 4,
            "elements": [
                "gregtech:wire_coil@8"
            ]
        },
        {
            "x": 0,
            "y": 1,
            "z": 4,
            "elements": [
                "gregtech:wire_coil@8"
            ]
        },
        {
            "x": 1,
            "y": 1,
            "z": 4,
            "elements": [
                "gregtech:wire_coil@8"
            ]
        },
        {
            "x": 2,
            "y": 1,
            "z": 4,
            "elements": [
                "techreborn:fusion_coil@0"
            ]
        },
        {
            "x": -2,
            "y": 4,
            "z": 1,
            "elements": [
                "modularmachinery:blockcasing",
                "modularmachinery:blockinputitem",
                "modularmachinery:blockinputenergy",
                "modularmachinery:blockoutputitem"
            ]
        },
        {
            "x": -2,
            "y": 2,
            "z": 0,
            "elements": [
                "techreborn:fusion_coil@0"
            ]
        },
        {
            "x": -1,
            "y": 4,
            "z": 1,
            "elements": [
                "modularmachinery:blockcasing",
                "modularmachinery:blockinputitem",
                "modularmachinery:blockinputenergy",
                "modularmachinery:blockoutputitem"
            ]
        },
        {
            "x": 0,
            "y": 4,
            "z": 1,
            "elements": [
                "modularmachinery:blockcasing",
                "modularmachinery:blockinputitem",
                "modularmachinery:blockinputenergy",
                "modularmachinery:blockoutputitem"
            ]
        },
        {
            "x": -1,
            "y": 2,
            "z": 0,
            "elements": [
                "gregtech:wire_coil@8"
            ]
        },
        {
            "x": 1,
            "y": 4,
            "z": 1,
            "elements": [
                "modularmachinery:blockcasing",
                "modularmachinery:blockinputitem",
                "modularmachinery:blockinputenergy",
                "modularmachinery:blockoutputitem"
            ]
        },
        {
            "x": 0,
            "y": 2,
            "z": 0,
            "elements": [
                "gregtech:wire_coil@8"
            ]
        },
        {
            "x": 2,
            "y": 4,
            "z": 1,
            "elements": [
                "modularmachinery:blockcasing",
                "modularmachinery:blockinputitem",
                "modularmachinery:blockinputenergy",
                "modularmachinery:blockoutputitem"
            ]
        },
        {
            "x": 1,
            "y": 2,
            "z": 0,
            "elements": [
                "gregtech:wire_coil@8"
            ]
        },
        {
            "x": -2,
            "y": 2,
            "z": 4,
            "elements": [
                "techreborn:fusion_coil@0"
            ]
        },
        {
            "x": 2,
            "y": 2,
            "z": 0,
            "elements": [
                "techreborn:fusion_coil@0"
            ]
        },
        {
            "x": -2,
            "y": 0,
            "z": 3,
            "elements": [
                "modularmachinery:blockcasing",
                "modularmachinery:blockinputitem",
                "modularmachinery:blockinputenergy",
                "modularmachinery:blockoutputitem"
            ]
        },
        {
            "x": -1,
            "y": 2,
            "z": 4,
            "elements": [
                "gregtech:wire_coil@8"
            ]
        },
        {
            "x": 0,
            "y": 2,
            "z": 4,
            "elements": [
                "gregtech:wire_coil@8"
            ]
        },
        {
            "x": -1,
            "y": 0,
            "z": 3,
            "elements": [
                "modularmachinery:blockcasing",
                "modularmachinery:blockinputitem",
                "modularmachinery:blockinputenergy",
                "modularmachinery:blockoutputitem"
            ]
        },
        {
            "x": 0,
            "y": 0,
            "z": 3,
            "elements": [
                "modularmachinery:blockcasing",
                "modularmachinery:blockinputitem",
                "modularmachinery:blockinputenergy",
                "modularmachinery:blockoutputitem"
            ]
        },
        {
            "x": 1,
            "y": 2,
            "z": 4,
            "elements": [
                "gregtech:wire_coil@8"
            ]
        },
        {
            "x": 2,
            "y": 2,
            "z": 4,
            "elements": [
                "techreborn:fusion_coil@0"
            ]
        },
        {
            "x": 1,
            "y": 0,
            "z": 3,
            "elements": [
                "modularmachinery:blockcasing",
                "modularmachinery:blockinputitem",
                "modularmachinery:blockinputenergy",
                "modularmachinery:blockoutputitem"
            ]
        },
        {
            "x": 2,
            "y": 0,
            "z": 3,
            "elements": [
                "modularmachinery:blockcasing",
                "modularmachinery:blockinputitem",
                "modularmachinery:blockinputenergy",
                "modularmachinery:blockoutputitem"
            ]
        },
        {
            "x": -2,
            "y": 3,
            "z": 0,
            "elements": [
                "techreborn:fusion_coil@0"
            ]
        },
        {
            "x": -1,
            "y": 3,
            "z": 0,
            "elements": [
                "gregtech:wire_coil@8"
            ]
        },
        {
            "x": 0,
            "y": 3,
            "z": 0,
            "elements": [
                "gregtech:wire_coil@8"
            ]
        },
        {
            "x": 1,
            "y": 3,
            "z": 0,
            "elements": [
                "gregtech:wire_coil@8"
            ]
        },
        {
            "x": -2,
            "y": 3,
            "z": 4,
            "elements": [
                "techreborn:fusion_coil@0"
            ]
        },
        {
            "x": 2,
            "y": 3,
            "z": 0,
            "elements": [
                "techreborn:fusion_coil@0"
            ]
        },
        {
            "x": -2,
            "y": 1,
            "z": 3,
            "elements": [
                "gregtech:wire_coil@8"
            ]
        },
        {
            "x": -1,
            "y": 3,
            "z": 4,
            "elements": [
                "gregtech:wire_coil@8"
            ]
        },
        {
            "x": 0,
            "y": 3,
            "z": 4,
            "elements": [
                "gregtech:wire_coil@8"
            ]
        },
        {
            "x": -1,
            "y": 1,
            "z": 3,
            "elements": [
                "gregtech:machine_casing@9"
            ]
        },
        {
            "x": 1,
            "y": 3,
            "z": 4,
            "elements": [
                "gregtech:wire_coil@8"
            ]
        },
        {
            "x": 0,
            "y": 1,
            "z": 3,
            "elements": [
                "gregtech:machine_casing@9"
            ]
        },
        {
            "x": 2,
            "y": 3,
            "z": 4,
            "elements": [
                "techreborn:fusion_coil@0"
            ]
        },
        {
            "x": 1,
            "y": 1,
            "z": 3,
            "elements": [
                "gregtech:machine_casing@9"
            ]
        },
        {
            "x": 2,
            "y": 1,
            "z": 3,
            "elements": [
                "gregtech:wire_coil@8"
            ]
        },
        {
            "x": -2,
            "y": 4,
            "z": 0,
            "elements": [
                "modularmachinery:blockcasing",
                "modularmachinery:blockinputitem",
                "modularmachinery:blockinputenergy",
                "modularmachinery:blockoutputitem"
            ]
        },
        {
            "x": -1,
            "y": 4,
            "z": 0,
            "elements": [
                "modularmachinery:blockcasing",
                "modularmachinery:blockinputitem",
                "modularmachinery:blockinputenergy",
                "modularmachinery:blockoutputitem"
            ]
        },
        {
            "x": 0,
            "y": 4,
            "z": 0,
            "elements": [
                "modularmachinery:blockcasing",
                "modularmachinery:blockinputitem",
                "modularmachinery:blockinputenergy",
                "modularmachinery:blockoutputitem"
            ]
        },
        {
            "x": 1,
            "y": 4,
            "z": 0,
            "elements": [
                "modularmachinery:blockcasing",
                "modularmachinery:blockinputitem",
                "modularmachinery:blockinputenergy",
                "modularmachinery:blockoutputitem"
            ]
        },
        {
            "x": -2,
            "y": 4,
            "z": 4,
            "elements": [
                "modularmachinery:blockcasing",
                "modularmachinery:blockinputitem",
                "modularmachinery:blockinputenergy",
                "modularmachinery:blockoutputitem"
            ]
        },
        {
            "x": 2,
            "y": 4,
            "z": 0,
            "elements": [
                "modularmachinery:blockcasing",
                "modularmachinery:blockinputitem",
                "modularmachinery:blockinputenergy",
                "modularmachinery:blockoutputitem"
            ]
        },
        {
            "x": -2,
            "y": 2,
            "z": 3,
            "elements": [
                "gregtech:wire_coil@8"
            ]
        },
        {
            "x": -1,
            "y": 4,
            "z": 4,
            "elements": [
                "modularmachinery:blockcasing",
                "modularmachinery:blockinputitem",
                "modularmachinery:blockinputenergy",
                "modularmachinery:blockoutputitem"
            ]
        },
        {
            "x": 0,
            "y": 4,
            "z": 4,
            "elements": [
                "modularmachinery:blockcasing",
                "modularmachinery:blockinputitem",
                "modularmachinery:blockinputenergy",
                "modularmachinery:blockoutputitem"
            ]
        },
        {
            "x": -2,
            "y": 0,
            "z": 2,
            "elements": [
                "modularmachinery:blockcasing",
                "modularmachinery:blockinputitem",
                "modularmachinery:blockinputenergy",
                "modularmachinery:blockoutputitem"
            ]
        },
        {
            "x": -1,
            "y": 2,
            "z": 3,
            "elements": [
                "gregtech:machine_casing@9"
            ]
        },
        {
            "x": 1,
            "y": 4,
            "z": 4,
            "elements": [
                "modularmachinery:blockcasing",
                "modularmachinery:blockinputitem",
                "modularmachinery:blockinputenergy",
                "modularmachinery:blockoutputitem"
            ]
        },
        {
            "x": 0,
            "y": 2,
            "z": 3,
            "elements": [
                "gregtech:machine_casing@9"
            ]
        },
        {
            "x": -1,
            "y": 0,
            "z": 2,
            "elements": [
                "modularmachinery:blockcasing",
                "modularmachinery:blockinputitem",
                "modularmachinery:blockinputenergy",
                "modularmachinery:blockoutputitem"
            ]
        },
        {
            "x": 0,
            "y": 0,
            "z": 2,
            "elements": [
                "modularmachinery:blockcasing",
                "modularmachinery:blockinputitem",
                "modularmachinery:blockinputenergy",
                "modularmachinery:blockoutputitem"
            ]
        },
        {
            "x": 2,
            "y": 4,
            "z": 4,
            "elements": [
                "modularmachinery:blockcasing",
                "modularmachinery:blockinputitem",
                "modularmachinery:blockinputenergy",
                "modularmachinery:blockoutputitem"
            ]
        },
        {
            "x": 1,
            "y": 2,
            "z": 3,
            "elements": [
                "gregtech:machine_casing@9"
            ]
        },
        {
            "x": 2,
            "y": 2,
            "z": 3,
            "elements": [
                "gregtech:wire_coil@8"
            ]
        },
        {
            "x": 1,
            "y": 0,
            "z": 2,
            "elements": [
                "modularmachinery:blockcasing",
                "modularmachinery:blockinputitem",
                "modularmachinery:blockinputenergy",
                "modularmachinery:blockoutputitem"
            ]
        },
        {
            "x": 2,
            "y": 0,
            "z": 2,
            "elements": [
                "modularmachinery:blockcasing",
                "modularmachinery:blockinputitem",
                "modularmachinery:blockinputenergy",
                "modularmachinery:blockoutputitem"
            ]
        },
        {
            "x": -2,
            "y": 3,
            "z": 3,
            "elements": [
                "gregtech:wire_coil@8"
            ]
        },
        {
            "x": -2,
            "y": 1,
            "z": 2,
            "elements": [
                "gregtech:wire_coil@8"
            ]
        },
        {
            "x": -1,
            "y": 3,
            "z": 3,
            "elements": [
                "gregtech:machine_casing@9"
            ]
        },
        {
            "x": 0,
            "y": 3,
            "z": 3,
            "elements": [
                "gregtech:machine_casing@9"
            ]
        },
        {
            "x": -1,
            "y": 1,
            "z": 2,
            "elements": [
                "gregtech:machine_casing@9"
            ]
        },
        {
            "x": 1,
            "y": 3,
            "z": 3,
            "elements": [
                "gregtech:machine_casing@9"
            ]
        },
        {
            "x": 0,
            "y": 1,
            "z": 2,
            "elements": [
                "gregtech:machine_casing@9"
            ]
        },
        {
            "x": 2,
            "y": 3,
            "z": 3,
            "elements": [
                "gregtech:wire_coil@8"
            ]
        },
        {
            "x": 1,
            "y": 1,
            "z": 2,
            "elements": [
                "gregtech:machine_casing@9"
            ]
        },
        {
            "x": 2,
            "y": 1,
            "z": 2,
            "elements": [
                "gregtech:wire_coil@8"
            ]
        },
        {
            "x": -2,
            "y": 4,
            "z": 3,
            "elements": [
                "modularmachinery:blockcasing",
                "modularmachinery:blockinputitem",
                "modularmachinery:blockinputenergy",
                "modularmachinery:blockoutputitem"
            ]
        },
        {
            "x": -2,
            "y": 2,
            "z": 2,
            "elements": [
                "gregtech:wire_coil@8"
            ]
        },
        {
            "x": -1,
            "y": 4,
            "z": 3,
            "elements": [
                "modularmachinery:blockcasing",
                "modularmachinery:blockinputitem",
                "modularmachinery:blockinputenergy",
                "modularmachinery:blockoutputitem"
            ]
        },
        {
            "x": 0,
            "y": 4,
            "z": 3,
            "elements": [
                "modularmachinery:blockcasing",
                "modularmachinery:blockinputitem",
                "modularmachinery:blockinputenergy",
                "modularmachinery:blockoutputitem"
            ]
        },
        {
            "x": -2,
            "y": 0,
            "z": 1,
            "elements": [
                "modularmachinery:blockcasing",
                "modularmachinery:blockinputitem",
                "modularmachinery:blockinputenergy",
                "modularmachinery:blockoutputitem"
            ]
        },
        {
            "x": -1,
            "y": 2,
            "z": 2,
            "elements": [
                "gregtech:machine_casing@9"
            ]
        },
        {
            "x": 1,
            "y": 4,
            "z": 3,
            "elements": [
                "modularmachinery:blockcasing",
                "modularmachinery:blockinputitem",
                "modularmachinery:blockinputenergy",
                "modularmachinery:blockoutputitem"
            ]
        },
        {
            "x": 0,
            "y": 2,
            "z": 2,
            "elements": [
                "gregtech:machine_casing@9"
            ]
        },
        {
            "x": -1,
            "y": 0,
            "z": 1,
            "elements": [
                "modularmachinery:blockcasing",
                "modularmachinery:blockinputitem",
                "modularmachinery:blockinputenergy",
                "modularmachinery:blockoutputitem"
            ]
        },
        {
            "x": 0,
            "y": 0,
            "z": 1,
            "elements": [
                "modularmachinery:blockcasing",
                "modularmachinery:blockinputitem",
                "modularmachinery:blockinputenergy",
                "modularmachinery:blockoutputitem"
            ]
        },
        {
            "x": 2,
            "y": 4,
            "z": 3,
            "elements": [
                "modularmachinery:blockcasing",
                "modularmachinery:blockinputitem",
                "modularmachinery:blockinputenergy",
                "modularmachinery:blockoutputitem"
            ]
        },
        {
            "x": 1,
            "y": 2,
            "z": 2,
            "elements": [
                "gregtech:machine_casing@9"
            ]
        },
        {
            "x": 2,
            "y": 2,
            "z": 2,
            "elements": [
                "gregtech:wire_coil@8"
            ]
        },
        {
            "x": 1,
            "y": 0,
            "z": 1,
            "elements": [
                "modularmachinery:blockcasing",
                "modularmachinery:blockinputitem",
                "modularmachinery:blockinputenergy",
                "modularmachinery:blockoutputitem"
            ]
        },
        {
            "x": 2,
            "y": 0,
            "z": 1,
            "elements": [
                "modularmachinery:blockcasing",
                "modularmachinery:blockinputitem",
                "modularmachinery:blockinputenergy",
                "modularmachinery:blockoutputitem"
            ]
        },
        {
            "x": -2,
            "y": 3,
            "z": 2,
            "elements": [
                "gregtech:wire_coil@8"
            ]
        },
        {
            "x": -2,
            "y": 1,
            "z": 1,
            "elements": [
                "gregtech:wire_coil@8"
            ]
        },
        {
            "x": -1,
            "y": 3,
            "z": 2,
            "elements": [
                "gregtech:machine_casing@9"
            ]
        },
        {
            "x": 0,
            "y": 3,
            "z": 2,
            "elements": [
                "gregtech:machine_casing@9"
            ]
        },
        {
            "x": -1,
            "y": 1,
            "z": 1,
            "elements": [
                "gregtech:machine_casing@9"
            ]
        },
        {
            "x": 1,
            "y": 3,
            "z": 2,
            "elements": [
                "gregtech:machine_casing@9"
            ]
        },
        {
            "x": 0,
            "y": 1,
            "z": 1,
            "elements": [
                "gregtech:machine_casing@9"
            ]
        },
        {
            "x": 2,
            "y": 3,
            "z": 2,
            "elements": [
                "gregtech:wire_coil@8"
            ]
        },
        {
            "x": 1,
            "y": 1,
            "z": 1,
            "elements": [
                "gregtech:machine_casing@9"
            ]
        },
        {
            "x": 2,
            "y": 1,
            "z": 1,
            "elements": [
                "gregtech:wire_coil@8"
            ]
        },
        {
            "x": -2,
            "y": 4,
            "z": 2,
            "elements": [
                "modularmachinery:blockcasing",
                "modularmachinery:blockinputitem",
                "modularmachinery:blockinputenergy",
                "modularmachinery:blockoutputitem"
            ]
        },
        {
            "x": -2,
            "y": 2,
            "z": 1,
            "elements": [
                "gregtech:wire_coil@8"
            ]
        },
        {
            "x": -1,
            "y": 4,
            "z": 2,
            "elements": [
                "modularmachinery:blockcasing",
                "modularmachinery:blockinputitem",
                "modularmachinery:blockinputenergy",
                "modularmachinery:blockoutputitem"
            ]
        },
        {
            "x": 0,
            "y": 4,
            "z": 2,
            "nbt": {"casingColor":"16730368","id":"minecraft:tilecolorablemachinecomponent"},
            "elements": [
                "modularmachinery:blockcasing@0"
            ]
        },
        {
            "x": -1,
            "y": 2,
            "z": 1,
            "elements": [
                "gregtech:machine_casing@9"
            ]
        },
        {
            "x": 1,
            "y": 4,
            "z": 2,
            "elements": [
                "modularmachinery:blockcasing",
                "modularmachinery:blockinputitem",
                "modularmachinery:blockinputenergy",
                "modularmachinery:blockoutputitem"
            ]
        },
        {
            "x": 0,
            "y": 2,
            "z": 1,
            "elements": [
                "gregtech:machine_casing@9"
            ]
        }
    ]}